<?xml version="1.0"?>
<robot name="tortoisebot">

  <!-- Dummy root to fix KDL inertia warning -->
  <link name="dummy_root"/>
  <joint name="dummy_to_base" type="fixed">
    <parent link="dummy_root"/>
    <child link="base_link"/>
  </joint>

  <link name="base_link">
    <visual>
      <geometry>
        <box size="0.6 0.3 0.3"/>
      </geometry>
      <material name="silver">
        <color rgba="0.75 0.75 0.75 1"/>
      </material>
    </visual>
    <collision>
      <geometry>
        <box size="0.6 0.3 0.3"/>
      </geometry>
    </collision>
    <inertial>
      <mass value="1.0"/>
      <inertia ixx="0.015" iyy="0.0375" izz="0.0375" ixy="0" ixz="0" iyz="0"/>
    </inertial>
  </link>

  <link name="front_caster">
    <visual>
      <geometry>
        <box size="0.1 0.1 0.3"/>
      </geometry>
      <material name="red"/>
    </visual>
    <collision>
      <geometry>
        <box size="0.1 0.1 0.3"/>
      </geometry>
    </collision>
    <inertial>
      <mass value="0.1"/>
      <inertia ixx="0.00083" iyy="0.00083" izz="0.000167" ixy="0" ixz="0" iyz="0"/>
    </inertial>
  </link>

  <joint name="front_caster_joint" type="continuous">
    <axis xyz="0 0 1"/>
    <parent link="base_link"/>
    <child link="front_caster"/>
    <origin rpy="0 0 0" xyz="0.3 0 0"/>
  </joint>

  <link name="front_wheel">
    <visual>
      <geometry>
        <cylinder length="0.05" radius="0.035"/>
      </geometry>
      <material name="black">
        <color rgba="0 0 0 1"/>
      </material>
    </visual>
    <collision>
      <geometry>
        <cylinder length="0.05" radius="0.035"/>
       
      </geometry>
    </collision>
    <inertial>
      <mass value="0.1"/>
      <inertia ixx="5.1458e-5" iyy="5.1458e-5" izz="6.125e-5" ixy="0" ixz="0" iyz="0"/>
    </inertial>
  </link>

  <joint name="front_wheel_joint" type="continuous">
    <axis xyz="0 0 1"/>
    <parent link="front_caster"/>
    <child link="front_wheel"/>
    <origin rpy="-1.5708 0 0" xyz="0.05 0 -.15"/>
  </joint>

  <link name="right_wheel">
    <visual>
      <geometry>
        <cylinder length="0.05" radius="0.035"/>
      </geometry>
      <material name="black">
        <color rgba="0 0 0 1"/>
      </material>
    </visual>
    <collision>
      <geometry>
        <cylinder length="0.05" radius="0.035"/>
      </geometry>
    </collision>
    <inertial>
      <mass value="0.1"/>
      <inertia ixx="5.1458e-5" iyy="5.1458e-5" izz="6.125e-5" ixy="0" ixz="0" iyz="0"/>
    </inertial>
  </link>

  <joint name="right_wheel_joint" type="continuous">
    <axis xyz="0 0 1"/>
    <parent link="base_link"/>
    <child link="right_wheel"/>
    <origin rpy="-1.5708 0 0" xyz="-0.2825 -0.125 -.15"/>
  </joint>

  <link name="left_wheel">
    <visual>
      <geometry>
        <cylinder length="0.05" radius="0.035"/>
      </geometry>
      <material name="black">
        <color rgba="0 0 0 1"/>
      </material>
    </visual>
    <collision>
      <geometry>
        <cylinder length="0.05" radius="0.035"/>
      </geometry>
    </collision>
    <inertial>
      <mass value="0.1"/>
      <inertia ixx="5.1458e-5" iyy="5.1458e-5" izz="6.125e-5" ixy="0" ixz="0" iyz="0"/>
    </inertial>
  </link>

  <joint name="left_wheel_joint" type="continuous">
    <axis xyz="0 0 1"/>
    <parent link="base_link"/>
    <child link="left_wheel"/>
    <origin rpy="-1.5708 0 0" xyz="-0.2825 0.125 -.15"/>
  </joint>

    
  <gazebo>
    <plugin name="gazebo_ros_diff_drive" filename="libgazebo_ros_diff_drive.so">
      <ros>
        <remapping>cmd_vel:=/cmd_vel</remapping>
      </ros>
      <left_joint>left_wheel_joint</left_joint>
      <right_joint>right_wheel_joint</right_joint>
      <wheel_separation>0.25</wheel_separation>
      <wheel_diameter>0.07</wheel_diameter>
      <publish_odom>true</publish_odom>
      <odometry_topic>odom</odometry_topic>
      <odometry_frame>odom</odometry_frame>
      <robot_base_frame>base_link</robot_base_frame>
      <cmd_vel_topic>/cmd_vel</cmd_vel_topic>
    </plugin>
</gazebo>


  

</robot>
